<?xml version="1.0"?>
<robot xmlns:xacro="http://www.ros.org/wiki/xacro">
    <xacro:include filename="inertial_macros.xacro" />

    <material name="white">
        <color rgba="1 1 1 1" />
    </material>

    <material name="orange">
        <color rgba="1 0.3 0.1 1"/>
    </material>

    <material name="blue">
        <color rgba="0.2 0.2 1 1"/>
    </material>

    <material name="black">
        <color rgba="0 0 0 1"/>
    </material>

    <material name="red">
        <color rgba="1 0 0 1"/>
    </material>

<!-- BASE LINK-->
    <link name="base_link">
    
    </link>

<!-- CAHSSIS LINK-->
    <joint name="chassis_joint" type = "fixed">
        <parent link ="base_link" />
        <child link="chassis"/>
        <origin xyz="0.15 0 0"/>
    </joint>

    <link name="chassis">
        <visual>
            <geometry>
                <box size="0.408 0.075 0.057"/>
            </geometry>
            <material name="white"/>
        </visual>
        <collision>
            <origin xyz="0 0 0" rpy="0 0 0"/>
            <geometry>
                <box size="0.408 0.075 0.057"/>
            </geometry>
        </collision>
        <xacro:inertial_box mass="1.113" x="0.408" y="0.075" z="0.057">
            <origiin xyz="0 0 0" rpy="0 0 0"/>
        </xacro:inertial_box>
    </link>

    <gazebo reference="chassis">
        <material>Gazebo/White</material>
    </gazebo>

<!-- FRONT BUMPER-->

    <joint name="bumper_joint" type = "fixed">
        <parent link ="chassis" />
        <child link="front_bumper"/>
        <origin xyz="0.209 0 0"/>
    </joint>

    <link name="front_bumper">
        <visual>
            <geometry>
                <box size="0.01 0.265 0.0285"/>
            </geometry>
            <material name="white"/>
        </visual>
        <collision>
            <geometry>
                <box size="0.01 0.265 0.057"/>
            </geometry>
        </collision>
        <xacro:inertial_box mass="0.003" x="0.01" y="0.256" z="0.057">
            <origiin xyz="0 0 0" rpy="0 0 0"/>
        </xacro:inertial_box>
    </link>

<!--REAR LEFT WHEEL AXEL -->
    <joint name="rear_left_axel_joint" type="fixed">
        <parent link="chassis"/>
        <child link="rear_left_axel_link"/>
        <origin xyz="-0.156 0.059 0" rpy="-${pi/2} 0 0 "/>
    </joint>

    <link name="rear_left_axel_link">
        <visual>
            <geometry>
                <cylinder radius="0.024" length="0.043"/>
            </geometry>
            <material name="orange"/>
        </visual>
         <collision>
            <geometry>
                <cylinder radius="0.024" length="0.043"/>
            </geometry>
        </collision> 
        <xacro:inertial_cylinder mass="0.005" radius="0.024" length="0.05">
            <origiin xyz="0 0 0" rpy="0 0 0"/>
        </xacro:inertial_cylinder>
    </link>
    <gazebo reference="rear_left_axel_link">
        <material>Gazebo/Orange</material>
    </gazebo>

<!-- REAR RIGHT WHEEL AXEL -->

    <joint name="rear_right_axel_joint" type="fixed">
        <parent link="chassis"/>
        <child link="rear_right_axel_link"/>
        <origin xyz="-0.15 -0.059 0" rpy="${pi/2} 0 0 "/>
    </joint>

    <link name="rear_right_axel_link">
        <visual>
            <geometry>
                <cylinder radius="0.024" length="0.043"/>
            </geometry>
            <material name="orange"/>
        </visual>
         <collision>
            <geometry>
                <cylinder radius="0.024" length="0.043"/>
            </geometry>
        </collision>
        <xacro:inertial_cylinder mass="0.005" radius="0.024" length="0.05">
            <origiin xyz="0 0 0" rpy="0 0 0"/>
        </xacro:inertial_cylinder>
    </link>

    <gazebo reference="rear_right_axel_link">
        <material>Gazebo/Orange</material>
    </gazebo>
<!-- FRONT LEFT WHEEL AXEL -->

    <joint name="front_left_axel_joint" type="fixed">
        <parent link="chassis"/>
        <child link="front_left_axel_link"/>
        <origin xyz="0.145 0.059 0" rpy="-${pi/2} 0 0"/>
    </joint>

    <link name="front_left_axel_link">
        <visual>
            <geometry>
                <cylinder radius="0.024" length="0.043"/>
            </geometry>
            <material name="orange"/>
        </visual>
         <collision>
            <geometry>
                <cylinder radius="0.024" length="0.043"/>
            </geometry>
        </collision>
        <xacro:inertial_cylinder mass="0.005" radius="0.024" length="0.05">
            <origiin xyz="0 0 0" rpy="0 0 0"/>
        </xacro:inertial_cylinder>
    </link>

    <gazebo reference="front_left_axel_link">
        <material>Gazebo/Orange</material>
    </gazebo>

<!-- FRONT RIGHT WHEEL AXEL -->
    <joint name="front_right_axel_joint" type="fixed">
        <parent link="chassis"/>
        <child link="front_right_axel_link"/>
        <origin xyz="0.145 -0.059 0" rpy="${pi/2} 0 0"/>
    </joint>

    <link name="front_right_axel_link">
        <visual>
            <geometry>
                <cylinder radius="0.024" length="0.043"/>
            </geometry>
            <material name="orange"/>
        </visual>
         <collision>
            <geometry>
                <cylinder radius="0.024" length="0.043"/>
            </geometry>
        </collision>
        <xacro:inertial_cylinder mass="0.005" radius="0.024" length="0.05">
            <origiin xyz="0 0 0" rpy="0 0 0"/>
        </xacro:inertial_cylinder>
    </link>

    <gazebo reference="front_right_axel_link">
        <material>Gazebo/Orange</material>
    </gazebo>

<!-- FRONT LEFT WHEEL -->

    <joint name="front_left_wheel_joint" type="continuous">
        <parent link="front_left_axel_link"/>
        <child link="front_left_wheel"/>
        <origin xyz="0 0 0.044" rpy="0 0 0"/>
        <axis xyz="0 0 1"/>
    </joint>

    <link name="front_left_wheel">
        <visual>
            <geometry>
                <cylinder radius="0.0483" length="0.045"/>
            </geometry>
            <material name="blue"/>
        </visual>
         <collision>
            <geometry>
                <cylinder radius="0.0483" length="0.045"/>
            </geometry>
        </collision>
        <xacro:inertial_cylinder mass="0.003" radius="0.0483" length="0.045">
            <origiin xyz="0 0 0" rpy="0 0 0"/>
        </xacro:inertial_cylinder>
    </link>

    <gazebo reference="front_left_wheel">
        <material>Gazebo/Blue</material>
        <mu1 value="0.001"/>
        <mu2 value="0.001"/>
    </gazebo>

<!-- FRONT RIGHT WHEEL -->

    <joint name="front_right_wheel_joint" type="continuous">
        <parent link="front_right_axel_link"/>
        <child link="front_right_wheel"/>
        <origin xyz="0 0 0.044" rpy="0 0 0"/>
        <axis xyz="0 0 -1"/>
    </joint>

    <link name="front_right_wheel">
        <visual>
            <geometry>
                <cylinder radius="0.0483" length="0.045"/>
            </geometry>
            <material name="blue"/>
        </visual>
         <collision>
            <geometry>
                <cylinder radius="0.0483" length="0.045"/>
            </geometry>
        </collision>
        <xacro:inertial_cylinder mass="0.003" radius="0.0483" length="0.045">
            <origiin xyz="0 0 0" rpy="0 0 0"/>
        </xacro:inertial_cylinder>
    </link>

    <gazebo reference="front_right_wheel">
        <material>Gazebo/Blue</material>
        <mu1 value="0.001"/>
        <mu2 value="0.001"/>
    </gazebo>

<!-- BACK LEFT WHEEL -->

    <joint name="rear_left_wheel_joint" type="continuous">
        <parent link="rear_left_axel_link"/>
        <child link="rear_left_wheel"/>
        <origin xyz="0 0 0.044" rpy="0 0 0"/>
        <axis xyz="0 0 1"/>
    </joint>

    <link name="rear_left_wheel">
        <visual>
            <geometry>
                <cylinder radius="0.0483" length="0.045"/>
            </geometry>
            <material name="blue"/>
        </visual>
         <collision>
            <geometry>
                <cylinder radius="0.0483" length="0.045"/>
            </geometry>
        </collision>
        <xacro:inertial_cylinder mass="0.003" radius="0.0483" length="0.045">
            <origiin xyz="0 0 0" rpy="0 0 0"/>
        </xacro:inertial_cylinder>
    </link>

    <gazebo reference="rear_left_wheel">
        <material>Gazebo/Blue</material>
    </gazebo>

<!-- BACK RIGHT WHEEL -->
    <joint name="rear_right_wheel_joint" type="continuous">
        <parent link="rear_right_axel_link"/>
        <child link="rear_right_wheel"/>
        <origin xyz="0 0 0.044" rpy="0 0 0"/>
        <axis xyz="0 0 -1"/>
    </joint>

    <link name="rear_right_wheel">
        <visual>
            <geometry>
                <cylinder radius="0.0483" length="0.045"/>
            </geometry>
            <material name="blue"/>
        </visual>
         <collision>
            <geometry>
                <cylinder radius="0.0483" length="0.045"/>
            </geometry>
        </collision>
        <xacro:inertial_cylinder mass="0.003" radius="0.0483" length="0.045">
            <origiin xyz="0 0 0" rpy="0 0 0"/>
        </xacro:inertial_cylinder>
    </link>

    <gazebo reference="rear_right_wheel">
        <material>Gazebo/Blue</material>
    </gazebo>
</robot>